Workbook

Sheet Daily View
A2: Teaching Studio MVP - provisional 28 working days
A3: Select Day 1 to Day 28 to view the shared functionality and four individual assignments.
A5: Select day | B5: Day 1 | G5: Overall completion | H5: =AVERAGE(Schedule!$K$6:$K$117)
A7: Shared functionality | B7: =IF(COUNTIFS(Schedule!$A$6:$A$117,$B$5)=0,"Select a valid day",INDEX(Schedule!$B$6:$B$117,MATCH($B$5,Schedule!$A$6:$A$117,0)))
A8: Whole-team outcome | B8: =IF(COUNTIFS(Schedule!$A$6:$A$117,$B$5)=0,"",INDEX(Schedule!$C$6:$C$117,MATCH($B$5,Schedule!$A$6:$A$117,0)))
A9: Day accepted when | B9: =IF(COUNTIFS(Schedule!$A$6:$A$117,$B$5)=0,"",INDEX(Schedule!$I$6:$I$117,MATCH($B$5,Schedule!$A$6:$A$117,0)))
A11: Team member | B11: Role | C11: Individual task | D11: Expected output | E11: Status | G11: Project status | H11: Value | I11: Meaning | J11: Action
A12: =IF(COUNTIFS(Schedule!$A$6:$A$117,$B$5)=0,"",INDEX(Schedule!$D$6:$D$117,MATCH($B$5,Schedule!$A$6:$A$117,0))) | B12: =IF($A12="","",INDEX(Schedule!$E$6:$E$117,MATCH($B$5,Schedule!$A$6:$A$117,0))) | C12: =IF($A12="","No work for the selected day",INDEX(Schedule!$F$6:$F$117,MATCH($B$5,Schedule!$A$6:$A$117,0))) | D12: =IF($A12="","",INDEX(Schedule!$G$6:$G$117,MATCH($B$5,Schedule!$A$6:$A$117,0))) | E12: =IF($A12="","—",INDEX(Schedule!$J$6:$J$117,MATCH($B$5,Schedule!$A$6:$A$117,0))) | G12: Tasks completed | H12: =COUNTIFS(Schedule!$J$6:$J$117,"Complete") | I12: Individual assignments completed | J12: Update each person’s row separately
A13: =IF(COUNTIFS(Schedule!$A$6:$A$117,$B$5)=0,"",INDEX(Schedule!$D$6:$D$117,MATCH($B$5,Schedule!$A$6:$A$117,0)+1)) | B13: =IF($A13="","",INDEX(Schedule!$E$6:$E$117,MATCH($B$5,Schedule!$A$6:$A$117,0)+1)) | C13: =IF($A13="","No work for the selected day",INDEX(Schedule!$F$6:$F$117,MATCH($B$5,Schedule!$A$6:$A$117,0)+1)) | D13: =IF($A13="","",INDEX(Schedule!$G$6:$G$117,MATCH($B$5,Schedule!$A$6:$A$117,0)+1)) | E13: =IF($A13="","—",INDEX(Schedule!$J$6:$J$117,MATCH($B$5,Schedule!$A$6:$A$117,0)+1)) | G13: Days completed | H13: =IF(COUNTIFS(Schedule!$A$6:$A$117,"Day 1",Schedule!$J$6:$J$117,"Complete")=4,1,0)+IF(COUNTIFS(Schedule!$A$6:$A$117,"Day 2",Schedule!$J$6:$J$117,"Complete")=4,1,0)+IF(COUNTIFS(Schedule!$A$6:$A$117,"Day 3",Schedule!$J$6:$J$117,"Complete")=4,1,0)+IF(COUNTIFS(Schedule!$A$6:$A$117,"Day 4",Schedule!$J$6:$J$117,"Complete")=4,1,0)+IF(COUNTIFS(Schedule!$A$6:$A$117,"Day 5",Schedule!$J$6:$J$117,"Complete")=4,1,0)+IF(COUNTIFS(Schedule!$A$6:$A$117,"Day 6",Schedule!$J$6:$J$117,"Complete")=4,1,0)+IF(COUNTIFS(Schedule!$A$6:$A$117,"Day 7",Schedule!$J$6:$J$117,"Complete")=4,1,0)+IF(COUNTIFS(Schedule!$A$6:$A$117,"Day 8",Schedule!$J$6:$J$117,"Complete")=4,1,0)+IF(COUNTIFS(Schedule!$A$6:$A$117,"Day 9",Schedule!$J$6:$J$117,"Complete")=4,1,0)+IF(COUNTIFS(Schedule!$A$6:$A$117,"Day 10",Schedule!$J$6:$J$117,"Complete")=4,1,0)+IF(COUNTIFS(Schedule!$A$6:$A$117,"Day 11",Schedule!$J$6:$J$117,"Complete")=4,1,0)+IF(COUNTIFS(Schedule!$A$6:$A$117,"Day 12",Schedule!$J$6:$J$117,"Complete")=4,1,0)+IF(COUNTIFS(Schedule!$A$6:$A$117,"Day 13",Schedule!$J$6:$J$117,"Complete")=4,1,0)+IF(COUNTIFS(Schedule!$A$6:$A$117,"Day 14",Schedule!$J$6:$J$117,"Complete")=4,1,0)+IF(COUNTIFS(Schedule!$A$6:$A$117,"Day 15",Schedule!$J$6:$J$117,"Complete")=4,1,0)+IF(COUNTIFS(Schedule!$A$6:$A$117,"Day 16",Schedule!$J$6:$J$117,"Complete")=4,1,0)+IF(COUNTIFS(Schedule!$A$6:$A$117,"Day 17",Schedule!$J$6:$J$117,"Complete")=4,1,0)+IF(COUNTIFS(Schedule!$A$6:$A$117,"Day 18",Schedule!$J$6:$J$117,"Complete")=4,1,0)+IF(COUNTIFS(Schedule!$A$6:$A$117,"Day 19",Schedule!$J$6:$J$117,"Complete")=4,1,0)+IF(COUNTIFS(Schedule!$A$6:$A$117,"Day 20",Schedule!$J$6:$J$117,"Complete")=4,1,0)+IF(COUNTIFS(Schedule!$A$6:$A$117,"Day 21",Schedule!$J$6:$J$117,"Complete")=4,1,0)+IF(COUNTIFS(Schedule!$A$6:$A$117,"Day 22",Schedule!$J$6:$J$117,"Complete")=4,1,0)+IF(COUNTIFS(Schedule!$A$6:$A$117,"Day 23",Schedule!$J$6:$J$117,"Complete")=4,1,0)+IF(COUNTIFS(Schedule!$A$6:$A$117,"Day 24",Schedule!$J$6:$J$117,"Complete")=4,1,0)+IF(COUNTIFS(Schedule!$A$6:$A$117,"Day 25",Schedule!$J$6:$J$117,"Complete")=4,1,0)+IF(COUNTIFS(Schedule!$A$6:$A$117,"Day 26",Schedule!$J$6:$J$117,"Complete")=4,1,0)+IF(COUNTIFS(Schedule!$A$6:$A$117,"Day 27",Schedule!$J$6:$J$117,"Complete")=4,1,0)+IF(COUNTIFS(Schedule!$A$6:$A$117,"Day 28",Schedule!$J$6:$J$117,"Complete")=4,1,0) | I13: Full four-person workdays completed | J13: Close all four rows during the daily review
A14: =IF(COUNTIFS(Schedule!$A$6:$A$117,$B$5)=0,"",INDEX(Schedule!$D$6:$D$117,MATCH($B$5,Schedule!$A$6:$A$117,0)+2)) | B14: =IF($A14="","",INDEX(Schedule!$E$6:$E$117,MATCH($B$5,Schedule!$A$6:$A$117,0)+2)) | C14: =IF($A14="","No work for the selected day",INDEX(Schedule!$F$6:$F$117,MATCH($B$5,Schedule!$A$6:$A$117,0)+2)) | D14: =IF($A14="","",INDEX(Schedule!$G$6:$G$117,MATCH($B$5,Schedule!$A$6:$A$117,0)+2)) | E14: =IF($A14="","—",INDEX(Schedule!$J$6:$J$117,MATCH($B$5,Schedule!$A$6:$A$117,0)+2)) | G14: Days remaining | H14: =MAX(0,28-H13) | I14: Workdays still open | J14: Finish current work before pulling future tasks
A15: =IF(COUNTIFS(Schedule!$A$6:$A$117,$B$5)=0,"",INDEX(Schedule!$D$6:$D$117,MATCH($B$5,Schedule!$A$6:$A$117,0)+3)) | B15: =IF($A15="","",INDEX(Schedule!$E$6:$E$117,MATCH($B$5,Schedule!$A$6:$A$117,0)+3)) | C15: =IF($A15="","No work for the selected day",INDEX(Schedule!$F$6:$F$117,MATCH($B$5,Schedule!$A$6:$A$117,0)+3)) | D15: =IF($A15="","",INDEX(Schedule!$G$6:$G$117,MATCH($B$5,Schedule!$A$6:$A$117,0)+3)) | E15: =IF($A15="","—",INDEX(Schedule!$J$6:$J$117,MATCH($B$5,Schedule!$A$6:$A$117,0)+3)) | G15: Final planned day | H15: =Schedule!$A$117 | I15: Last day in the 28-day sequence | J15: Holidays do not consume a project day
G16: Current state | H16: =IF(COUNTIF(Schedule!$J$6:$J$117,"Blocked")>0,"Blocked",IF(COUNTIF(Schedule!$J$6:$J$117,"Needs verification")>0,"Needs verification",IF(H12=112,"Complete",IF(COUNTIF(Schedule!$J$6:$J$117,"In Progress")>0,"In Progress","Planned")))) | I16: Overall project state | J16: Record blockers in the Schedule sheet
A18: How the team uses this tracker
A19: 1 | B19: Start of day | C19: Read the shared feature, then each member starts only their own assigned row.
A20: 2 | B20: During the day | C20: Rahul, Poojitha and Dhanunjaya complete their rotating roles independently; Teja prepares and runs QA.
A21: 3 | B21: Before closing | C21: Each person updates status and evidence for their own row. Discuss blockers together.
A22: 4 | B22: End-of-day review | C22: Review all four outputs together and close the day only when the shared completion rule is met.

Sheet Schedule
A2: 28-working-day Teaching Studio MVP implementation plan ? corrected
A3: Provisional effort sequence, not a committed delivery date. Reuse React/Vite, Express, PostgreSQL/Supabase and existing LMS identity. Advance only after acceptance evidence; see Scope and Gates.
A5: Day | B5: Shared application functionality | C5: Whole-team outcome | D5: Team member | E5: Role | F5: Individual task | G5: Expected output | H5: Individual done when | I5: Day accepted when | J5: Status | K5: Progress | L5: Blocker / dependency | M5: Evidence / update
A6: Day 1 | B6: Project requirements and LMS integration scope | C6: Agree what Teaching Studio reuses from the LMS and what must be added. | D6: Rahul | E6: Backend | F6: Backend — Review LMS authentication, curriculum, content and teaching-session services; record reusable services. | G6: Reviewed LMS reuse/gap inventory and BR-01?BR-36 traceability entries for Backend | H6: Repository paths, existing capability, gap, owner and acceptance evidence are recorded; code delivery is not required for this analysis task. | I6: The team has one agreed reuse-and-gap baseline for the existing LMS. | J6: Needs verification | K6: 0 | L6: None | M6: Prior tracker claimed complete. Unverified in reviewed checkout. Claimed evidence: Team confirmed Day 1 complete. Attach commit, commands/results and reviewer before closing.
A7: Day 1 | B7: Project requirements and LMS integration scope | C7: Agree what Teaching Studio reuses from the LMS and what must be added. | D7: Poojitha | E7: Frontend | F7: Frontend — Review required Studio screens, layouts and resource flows; record UI gaps. | G7: Reviewed LMS reuse/gap inventory and BR-01?BR-36 traceability entries for Frontend | H7: Repository paths, existing capability, gap, owner and acceptance evidence are recorded; code delivery is not required for this analysis task. | I7: The team has one agreed reuse-and-gap baseline for the existing LMS. | J7: Needs verification | K7: 0 | L7: None | M7: Prior tracker claimed complete. Unverified in reviewed checkout. Claimed evidence: Team confirmed Day 1 complete. Attach commit, commands/results and reviewer before closing.
A8: Day 1 | B8: Project requirements and LMS integration scope | C8: Agree what Teaching Studio reuses from the LMS and what must be added. | D8: Dhanunjaya | E8: Database | F8: Database — Review the current LMS schema against Teaching Studio entities; record mapping gaps. | G8: Reviewed LMS reuse/gap inventory and BR-01?BR-36 traceability entries for Database | H8: Repository paths, existing capability, gap, owner and acceptance evidence are recorded; code delivery is not required for this analysis task. | I8: The team has one agreed reuse-and-gap baseline for the existing LMS. | J8: Needs verification | K8: 0 | L8: None | M8: Prior tracker claimed complete. Unverified in reviewed checkout. Claimed evidence: Team confirmed Day 1 complete. Attach commit, commands/results and reviewer before closing.
A9: Day 1 | B9: Project requirements and LMS integration scope | C9: Agree what Teaching Studio reuses from the LMS and what must be added. | D9: Teja | E9: QA | F9: QA — Create the first acceptance checklist from the BRD and guides. | G9: Reviewed LMS reuse/gap inventory and BR-01?BR-36 traceability entries for QA | H9: Repository paths, existing capability, gap, owner and acceptance evidence are recorded; code delivery is not required for this analysis task. | I9: The team has one agreed reuse-and-gap baseline for the existing LMS. | J9: Needs verification | K9: 0 | L9: None | M9: Prior tracker claimed complete. Unverified in reviewed checkout. Claimed evidence: Team confirmed Day 1 complete. Attach commit, commands/results and reviewer before closing.
A10: Day 2 | B10: Resource Library model and safe local setup | C10: Prepare the Resource Library architecture without changing hosted production data. | D10: Rahul | E10: Database | F10: Database — Draft resource items, versions, bindings and supporting tables; document the LMS identity mismatch. | G10: Reviewed resource schema/service/UI/test design for Database | H10: Design is mapped to current LMS integer identities and client/school scope; local-only execution and migration assumptions are documented. | I10: The schema draft, integration risks and local test approach are documented. | J10: Needs verification | K10: 0 | L10: Day 1 | M10: Prior tracker claimed complete. Unverified in reviewed checkout. Claimed evidence: review/day2_schema_review.md. Attach commit, commands/results and reviewer before closing.
A11: Day 2 | B11: Resource Library model and safe local setup | C11: Prepare the Resource Library architecture without changing hosted production data. | D11: Poojitha | E11: Backend | F11: Backend — Define resource, version and binding service boundaries and access rules. | G11: Reviewed resource schema/service/UI/test design for Backend | H11: Design is mapped to current LMS integer identities and client/school scope; local-only execution and migration assumptions are documented. | I11: The schema draft, integration risks and local test approach are documented. | J11: Needs verification | K11: 0 | L11: Day 1 | M11: Prior tracker claimed complete. Unverified in reviewed checkout. Claimed evidence: review/day2_schema_review.md. Attach commit, commands/results and reviewer before closing.
A12: Day 2 | B12: Resource Library model and safe local setup | C12: Prepare the Resource Library architecture without changing hosted production data. | D12: Dhanunjaya | E12: Frontend | F12: Frontend — Define the catalog, search, version and placement information required by the UI. | G12: Reviewed resource schema/service/UI/test design for Frontend | H12: Design is mapped to current LMS integer identities and client/school scope; local-only execution and migration assumptions are documented. | I12: The schema draft, integration risks and local test approach are documented. | J12: Needs verification | K12: 0 | L12: Day 1 | M12: Prior tracker claimed complete. Unverified in reviewed checkout. Claimed evidence: review/day2_schema_review.md. Attach commit, commands/results and reviewer before closing.
A13: Day 2 | B13: Resource Library model and safe local setup | C13: Prepare the Resource Library architecture without changing hosted production data. | D13: Teja | E13: QA | F13: QA — Prepare schema, version immutability and tenant-isolation test cases. | G13: Reviewed resource schema/service/UI/test design for QA | H13: Design is mapped to current LMS integer identities and client/school scope; local-only execution and migration assumptions are documented. | I13: The schema draft, integration risks and local test approach are documented. | J13: Needs verification | K13: 0 | L13: Day 1 | M13: Prior tracker claimed complete. Unverified in reviewed checkout. Claimed evidence: review/day2_schema_review.md. Attach commit, commands/results and reviewer before closing.
A14: Day 3 | B14: Integrated Teaching Studio authoring foundation in the LMS | C14: Establish the complete shared foundation: protected LMS access, the authoring workspace and layouts, safe local data setup, and QA coverage. | D14: Rahul | E14: Backend | F14: Backend — Connect the protected Studio route to existing LMS role access. | G14: Working API/service for Integrated Teaching Studio authoring foundation in the LMS | H14: The service/API works with permissions and error handling and is ready for QA. | I14: Role-based access works, the authoring workspace and layouts render, the local data foundation is usable, and QA has verified the combined flow. | J14: Needs verification | K14: 0 | L14: Days 1?2; confirm provisional LMS mapping before local implementation | M14: Prior tracker claimed complete. Unverified in reviewed checkout. Claimed evidence: docs/teaching-studio-day3.md. Attach commit, commands/results and reviewer before closing. Studio routes/canvas and cited day3 document were not found in reviewed application source; SQL files alone do not verify this gate.
A15: Day 3 | B15: Integrated Teaching Studio authoring foundation in the LMS | C15: Establish the complete shared foundation: protected LMS access, the authoring workspace and layouts, safe local data setup, and QA coverage. | D15: Poojitha | E15: Database | F15: Database — Prepare the local migration/seed foundation needed for safe Studio testing. | G15: Reviewed schema, migration or data change for Integrated Teaching Studio authoring foundation in the LMS | H15: The schema/query change runs locally, preserves integrity and is ready for QA. | I15: Role-based access works, the authoring workspace and layouts render, the local data foundation is usable, and QA has verified the combined flow. | J15: Needs verification | K15: 0 | L15: Days 1?2; confirm provisional LMS mapping before local implementation | M15: Prior tracker claimed complete. Unverified in reviewed checkout. Claimed evidence: docs/teaching-studio-day3.md. Attach commit, commands/results and reviewer before closing. Studio routes/canvas and cited day3 document were not found in reviewed application source; SQL files alone do not verify this gate.
A16: Day 3 | B16: Integrated Teaching Studio authoring foundation in the LMS | C16: Establish the complete shared foundation: protected LMS access, the authoring workspace and layouts, safe local data setup, and QA coverage. | D16: Dhanunjaya | E16: Frontend | F16: Frontend — Implement the 1920 × 1080 canvas, safe margins and 14 target layouts. | G16: Working UI/component for Integrated Teaching Studio authoring foundation in the LMS | H16: The UI works in the agreed flow and is ready for QA. | I16: Role-based access works, the authoring workspace and layouts render, the local data foundation is usable, and QA has verified the combined flow. | J16: Needs verification | K16: 0 | L16: Days 1?2; confirm provisional LMS mapping before local implementation | M16: Prior tracker claimed complete. Unverified in reviewed checkout. Claimed evidence: docs/teaching-studio-day3.md. Attach commit, commands/results and reviewer before closing. Studio routes/canvas and cited day3 document were not found in reviewed application source; SQL files alone do not verify this gate.
A17: Day 3 | B17: Integrated Teaching Studio authoring foundation in the LMS | C17: Establish the complete shared foundation: protected LMS access, the authoring workspace and layouts, safe local data setup, and QA coverage. | D17: Teja | E17: QA | F17: QA — Run layout, viewport, route-access, build and browser checks. | G17: Executed test results and defect update for Integrated Teaching Studio authoring foundation in the LMS | H17: Planned tests are executed, and pass/fail evidence and defects are recorded. | I17: Role-based access works, the authoring workspace and layouts render, the local data foundation is usable, and QA has verified the combined flow. | J17: Needs verification | K17: 0 | L17: Days 1?2; confirm provisional LMS mapping before local implementation | M17: Prior tracker claimed complete. Unverified in reviewed checkout. Claimed evidence: docs/teaching-studio-day3.md. Attach commit, commands/results and reviewer before closing. Studio routes/canvas and cited day3 document were not found in reviewed application source; SQL files alone do not verify this gate.
A18: Day 4 | B18: Confirm existing LMS tenant and curriculum mapping | C18: Review and accept the mapping already present in Studio SQL, then resolve remaining identity, school and academic-scope gaps. | D18: Rahul | E18: Frontend | F18: Frontend ? Map existing programme/grade/subject/chapter/topic selectors and role navigation to the approved Studio contract. | G18: Working UI/component for Tenant and curriculum integration decision | H18: The UI works in the agreed flow and is ready for QA. | I18: One reviewed adapter contract maps client_id, optional school_id, integer LMS users and academic IDs; Author authority and platform-owned content behavior are explicit. | J18: Planned | K18: 0 | L18: Days 1?3 evidence; review existing SQL 001?004
A19: Day 4 | B19: Confirm existing LMS tenant and curriculum mapping | C19: Review and accept the mapping already present in Studio SQL, then resolve remaining identity, school and academic-scope gaps. | D19: Poojitha | E19: Backend | F19: Backend ? Reuse existing JWT authentication, permission and entitlement services; map content_authorizer to scoped Author capabilities without granting blanket academic approval. | G19: Working API/service for Tenant and curriculum integration decision | H19: The service/API works with permissions and error handling and is ready for QA. | I19: One reviewed adapter contract maps client_id, optional school_id, integer LMS users and academic IDs; Author authority and platform-owned content behavior are explicit. | J19: Planned | K19: 0 | L19: Days 1?3 evidence; review existing SQL 001?004
A20: Day 4 | B20: Confirm existing LMS tenant and curriculum mapping | C20: Review and accept the mapping already present in Studio SQL, then resolve remaining identity, school and academic-scope gaps. | D20: Dhanunjaya | E20: Database | F20: Database ? Review existing Studio client/user/program/curriculum foreign keys and tenant constraints; document any required migration changes. | G20: Reviewed schema, migration or data change for Tenant and curriculum integration decision | H20: The schema/query change runs locally, preserves integrity and is ready for QA. | I20: One reviewed adapter contract maps client_id, optional school_id, integer LMS users and academic IDs; Author authority and platform-owned content behavior are explicit. | J20: Planned | K20: 0 | L20: Days 1?3 evidence; review existing SQL 001?004
A21: Day 4 | B21: Confirm existing LMS tenant and curriculum mapping | C21: Review and accept the mapping already present in Studio SQL, then resolve remaining identity, school and academic-scope gaps. | D21: Teja | E21: QA | F21: QA — Check the proposed mapping against cross-tenant, role and academic-scope scenarios. | G21: Executed test results and defect update for Tenant and curriculum integration decision | H21: Planned tests are executed, and pass/fail evidence and defects are recorded. | I21: One reviewed adapter contract maps client_id, optional school_id, integer LMS users and academic IDs; Author authority and platform-owned content behavior are explicit. | J21: Planned | K21: 0 | L21: Days 1?3 evidence; review existing SQL 001?004
A22: Day 5 | B22: Lesson, session and screen contract | C22: Define exactly what the Author creates and what the LMS stores. | D22: Rahul | E22: Database | F22: Database — Define lesson, session, screen, objective and ordering relationships. | G22: Reviewed lesson/session/screen/object contract for Database | H22: UI fields, service commands, existing/new tables, validation, revision handling and permission boundaries agree; implementation follows on Days 6?8. | I22: One reviewed contract covers UI fields, APIs, tables and validation. | J22: Planned | K22: 0 | L22: Day 4
A23: Day 5 | B23: Lesson, session and screen contract | C23: Define exactly what the Author creates and what the LMS stores. | D23: Poojitha | E23: Frontend | F23: Frontend — Define the lesson setup and screen-list fields shown to the Author. | G23: Reviewed lesson/session/screen/object contract for Frontend | H23: UI fields, service commands, existing/new tables, validation, revision handling and permission boundaries agree; implementation follows on Days 6?8. | I23: One reviewed contract covers UI fields, APIs, tables and validation. | J23: Planned | K23: 0 | L23: Day 4
A24: Day 5 | B24: Lesson, session and screen contract | C24: Define exactly what the Author creates and what the LMS stores. | D24: Dhanunjaya | E24: Backend | F24: Backend — Define create, read, update, reorder and validation API contracts. | G24: Reviewed lesson/session/screen/object contract for Backend | H24: UI fields, service commands, existing/new tables, validation, revision handling and permission boundaries agree; implementation follows on Days 6?8. | I24: One reviewed contract covers UI fields, APIs, tables and validation. | J24: Planned | K24: 0 | L24: Day 4
A25: Day 5 | B25: Lesson, session and screen contract | C25: Define exactly what the Author creates and what the LMS stores. | D25: Teja | E25: QA | F25: QA — Write happy-path, invalid-input and permission acceptance cases. | G25: Reviewed lesson/session/screen/object contract for QA | H25: UI fields, service commands, existing/new tables, validation, revision handling and permission boundaries agree; implementation follows on Days 6?8. | I25: One reviewed contract covers UI fields, APIs, tables and validation. | J25: Planned | K25: 0 | L25: Day 4
A26: Day 6 | B26: Studio persistence migration | C26: Validate and extend existing Studio SQL scripts 001?004 against a clean isolated PostgreSQL/Supabase database. | D26: Rahul | E26: Backend | F26: Backend — Add migration execution and service bootstrap needed by Studio. | G26: Working API/service for Studio persistence migration | H26: The service/API works with permissions and error handling and is ready for QA. | I26: Existing SQL plus reviewed changes run from a clean local database; tenant constraints, seed prerequisites and recovery are evidenced. No hosted production writes. | J26: Planned | K26: 0 | L26: Day 5
A27: Day 6 | B27: Studio persistence migration | C27: Validate and extend existing Studio SQL scripts 001?004 against a clean isolated PostgreSQL/Supabase database. | D27: Poojitha | E27: Database | F27: Database ? Reuse and review SQL 001?004; add only missing LMS-aligned persistence changes, with clean migration and integrity checks. | G27: Reviewed schema, migration or data change for Studio persistence migration | H27: The schema/query change runs locally, preserves integrity and is ready for QA. | I27: Existing SQL plus reviewed changes run from a clean local database; tenant constraints, seed prerequisites and recovery are evidenced. No hosted production writes. | J27: Planned | K27: 0 | L27: Day 5
A28: Day 6 | B28: Studio persistence migration | C28: Validate and extend existing Studio SQL scripts 001?004 against a clean isolated PostgreSQL/Supabase database. | D28: Dhanunjaya | E28: Frontend | F28: Frontend — Update frontend types and mock data to match the approved contract. | G28: Working UI/component for Studio persistence migration | H28: The UI works in the agreed flow and is ready for QA. | I28: Existing SQL plus reviewed changes run from a clean local database; tenant constraints, seed prerequisites and recovery are evidenced. No hosted production writes. | J28: Planned | K28: 0 | L28: Day 5
A29: Day 6 | B29: Studio persistence migration | C29: Validate and extend existing Studio SQL scripts 001?004 against a clean isolated PostgreSQL/Supabase database. | D29: Teja | E29: QA | F29: QA — Run the migration repeatedly in local Supabase and verify clean rollback/reset. | G29: Executed test results and defect update for Studio persistence migration | H29: Planned tests are executed, and pass/fail evidence and defects are recorded. | I29: Existing SQL plus reviewed changes run from a clean local database; tenant constraints, seed prerequisites and recovery are evidenced. No hosted production writes. | J29: Planned | K29: 0 | L29: Day 5
... A77: Day 18 | B77: Clarification branch and return state | C77: Let a Teacher open one clarification and return to the exact lesson position. | D77: Teja | E77: QA | F77: QA — Test entry, interaction, return, reveal-position retention and failure recovery. | G77: Executed test results and defect update for Clarification branch and return state | H77: Planned tests are executed, and pass/fail evidence and defects are recorded. | I77: Teacher branch preview returns to the same screen, reveal and supported interaction state; persisted run verification is repeated on Day 23. Learner payload omits private branches. | J77: Planned | K77: 0 | L77: Day 17; preview harness only until Day 23 release player
A78: Day 19 | B78: Security and accessibility hardening | C78: Protect private fields and make the MVP usable with keyboard and classroom projection. | D78: Rahul | E78: Frontend | F78: Frontend — Fix keyboard flow, labels, contrast, focus and projection readability. | G78: Working UI/component for Security and accessibility hardening | H78: The UI works in the agreed flow and is ready for QA. | I78: Signed-in Author/Teacher/Student cases verify client/school/scope restrictions, direct API and asset denial, private metadata omission, keyboard/focus and projection readability; no critical blocker remains. | J78: Planned | K78: 0 | L78: Days 11–18 | M78: Access checks start on Day 3 and apply to every API from first implementation; Day 19 consolidates hardening, not first security implementation.
A79: Day 19 | B79: Security and accessibility hardening | C79: Protect private fields and make the MVP usable with keyboard and classroom projection. | D79: Poojitha | E79: Backend | F79: Backend — Implement learner-safe/teacher-safe response projections and denial handling. | G79: Working API/service for Security and accessibility hardening | H79: The service/API works with permissions and error handling and is ready for QA. | I79: Signed-in Author/Teacher/Student cases verify client/school/scope restrictions, direct API and asset denial, private metadata omission, keyboard/focus and projection readability; no critical blocker remains. | J79: Planned | K79: 0 | L79: Days 11–18 | M79: Access checks start on Day 3 and apply to every API from first implementation; Day 19 consolidates hardening, not first security implementation.
A80: Day 19 | B80: Security and accessibility hardening | C80: Protect private fields and make the MVP usable with keyboard and classroom projection. | D80: Dhanunjaya | E80: Database | F80: Database — Review tenant constraints and RLS/grant expectations for Studio tables. | G80: Reviewed schema, migration or data change for Security and accessibility hardening | H80: The schema/query change runs locally, preserves integrity and is ready for QA. | I80: Signed-in Author/Teacher/Student cases verify client/school/scope restrictions, direct API and asset denial, private metadata omission, keyboard/focus and projection readability; no critical blocker remains. | J80: Planned | K80: 0 | L80: Days 11–18 | M80: Access checks start on Day 3 and apply to every API from first implementation; Day 19 consolidates hardening, not first security implementation.
A81: Day 19 | B81: Security and accessibility hardening | C81: Protect private fields and make the MVP usable with keyboard and classroom projection. | D81: Teja | E81: QA | F81: QA — Run permission, payload-leak, keyboard, contrast and responsive checks. | G81: Executed test results and defect update for Security and accessibility hardening | H81: Planned tests are executed, and pass/fail evidence and defects are recorded. | I81: Signed-in Author/Teacher/Student cases verify client/school/scope restrictions, direct API and asset denial, private metadata omission, keyboard/focus and projection readability; no critical blocker remains. | J81: Planned | K81: 0 | L81: Days 11–18 | M81: Access checks start on Day 3 and apply to every API from first implementation; Day 19 consolidates hardening, not first security implementation.
A82: Day 20 | B82: Author MVP review | C82: Prove the Author can build a screen and reuse an approved resource end to end. | D82: Rahul | E82: Database | F82: Database — Verify saved draft, version and binding data for the scenario. | G82: Reviewed schema, migration or data change for Author MVP review | H82: The schema/query change runs locally, preserves integrity and is ready for QA. | I82: Author creates, saves, reloads and previews a screen with an approved exact-version resource; validation findings and draft status are visible. This is an authoring gate, not production release approval. | J82: Planned | K82: 0 | L82: Days 11–19
A83: Day 20 | B83: Author MVP review | C83: Prove the Author can build a screen and reuse an approved resource end to end. | D83: Poojitha | E83: Frontend | F83: Frontend — Complete the Author journey and fix usability blockers. | G83: Working UI/component for Author MVP review | H83: The UI works in the agreed flow and is ready for QA. | I83: Author creates, saves, reloads and previews a screen with an approved exact-version resource; validation findings and draft status are visible. This is an authoring gate, not production release approval. | J83: Planned | K83: 0 | L83: Days 11–19
A84: Day 20 | B84: Author MVP review | C84: Prove the Author can build a screen and reuse an approved resource end to end. | D84: Dhanunjaya | E84: Backend | F84: Backend — Complete end-to-end orchestration and fix API blockers. | G84: Working API/service for Author MVP review | H84: The service/API works with permissions and error handling and is ready for QA. | I84: Author creates, saves, reloads and previews a screen with an approved exact-version resource; validation findings and draft status are visible. This is an authoring gate, not production release approval. | J84: Planned | K84: 0 | L84: Days 11–19
A85: Day 20 | B85: Author MVP review | C85: Prove the Author can build a screen and reuse an approved resource end to end. | D85: Teja | E85: QA | F85: QA — Run the Author acceptance scenario and record defects/evidence. | G85: Executed test results and defect update for Author MVP review | H85: Planned tests are executed, and pass/fail evidence and defects are recorded. | I85: Author creates, saves, reloads and previews a screen with an approved exact-version resource; validation findings and draft status are visible. This is an authoring gate, not production release approval. | J85: Planned | K85: 0 | L85: Days 11–19
A86: Day 21 | B86: Academic authorization workflow | C86: Record who authorizes which exact lesson revision and scope. | D86: Rahul | E86: Backend | F86: Backend — Implement authorization command, permissions and rejection handling. | G86: Working API/service for Academic authorization workflow | H86: The service/API works with permissions and error handling and is ready for QA. | I86: Only a scoped permitted Author can approve an exact validated lesson revision/hash; record rationale, timestamp and validator version. Changes invalidate prior approval for the changed revision. | J86: Planned | K86: 0 | L86: Day 20
A87: Day 21 | B87: Academic authorization workflow | C87: Record who authorizes which exact lesson revision and scope. | D87: Poojitha | E87: Database | F87: Database — Persist authorizer, exact revision, scope, decision and timestamp. | G87: Reviewed schema, migration or data change for Academic authorization workflow | H87: The schema/query change runs locally, preserves integrity and is ready for QA. | I87: Only a scoped permitted Author can approve an exact validated lesson revision/hash; record rationale, timestamp and validator version. Changes invalidate prior approval for the changed revision. | J87: Planned | K87: 0 | L87: Day 20
A88: Day 21 | B88: Academic authorization workflow | C88: Record who authorizes which exact lesson revision and scope. | D88: Dhanunjaya | E88: Frontend | F88: Frontend — Build review summary, authorize/reject action and reason display. | G88: Working UI/component for Academic authorization workflow | H88: The UI works in the agreed flow and is ready for QA. | I88: Only a scoped permitted Author can approve an exact validated lesson revision/hash; record rationale, timestamp and validator version. Changes invalidate prior approval for the changed revision. | J88: Planned | K88: 0 | L88: Day 20
A89: Day 21 | B89: Academic authorization workflow | C89: Record who authorizes which exact lesson revision and scope. | D89: Teja | E89: QA | F89: QA — Test permitted authorizer, denied roles, rejection and changed-draft reauthorization. | G89: Executed test results and defect update for Academic authorization workflow | H89: Planned tests are executed, and pass/fail evidence and defects are recorded. | I89: Only a scoped permitted Author can approve an exact validated lesson revision/hash; record rationale, timestamp and validator version. Changes invalidate prior approval for the changed revision. | J89: Planned | K89: 0 | L89: Day 20
...

Sheet Scope and Gates
A1: Topic | B1: Corrected planning rule | C1: Acceptance / evidence
A2: Purpose | B2: Deliver an initial governed authoring, resource reuse and classroom delivery MVP in 28 provisional working days. | C2: This workbook is a plan, not evidence of completed functionality or a guarantee of duration.
A3: Existing stack | B3: React 19/Vite/TypeScript; Express/Node; PostgreSQL/Supabase; existing LMS JWT auth, permissions and entitlements. | C3: Reuse repository services; no Cloudflare Worker/D1 platform migration is included.
A4: Existing data | B4: Review Studio SQL 001?004 rather than create duplicate parallel models. Existing SQL uses client_id, school_id, integer LMS user and academic references; Studio entities use UUIDs. | C4: Inspect constraints, applied migration state and data in an isolated environment. SQL files do not prove live database deployment.
A5: Authority | B5: Map content_authorizer and other permitted LMS roles to explicitly scoped Studio commands. Platform ownership is not academic authorization. | C5: Reviewed role/scope/entitlement matrix, denied-write tests and same-tenant relationships.
A6: MVP authoring | B6: Lesson/session/screen drafts; structured text, visual, question and resource objects; saved ordering; supported layouts; basic reveals; conflict handling. | C6: Save/reload and unrelated-content preservation tests. Scope supported object/layout types before build.
A7: MVP resource routes | B7: Native text/simple quiz; agreed image/PDF upload; reviewed HTTPS link; internal-map reuse. | C7: Declare exact formats, limits, rights, accessibility, fallback and preview behavior. Arbitrary source projects and conversation URLs are not executable content.
A8: MVP library | B8: Items, exact versions, scoped academic mappings, search/type/subject/grade filters, pagination, review, bindings, referenced-version protection and withdrawal. | C8: One exact approved version in two lessons with independent teaching context; no silent replacement.
A9: MVP release and delivery | B9: Validate exact revision, academic approval, immutable pinned release, Teacher run, branch return, student-safe projection. | C9: Any later draft/resource candidate leaves active releases and runs unchanged.
A10: Mandatory privacy | B10: Apply permissions from the first route. Hide private data server-side, including assets and metadata. Student-safe payload checks remain in scope. | C10: Real signed-in role tests plus direct API/file denial and cross-client/school/scope tests.
A11: Status integrity | B11: Days 1?3 changed from Complete to Needs verification; old evidence references retained as unverified claims. | C11: Attach repository revision, actual path/report, executed commands/results and reviewer before setting Complete.
A12: Integration gate | B12: Day 4 confirms the mapping already represented in SQL and resolves gaps. Do not design a second tenant or curriculum system. | C12: Approved adapter and migration contract before persisted feature work.
... A22: Review basis | B22: BRD v3 and Developer Guide v3 dated 8 October 2026; both supplied Excel files; local LMS source inspected 15 October 2026. | C22: Static review only: hosted state, cited completion evidence and full browser execution were not verified.

Sheet Follow-up Backlog
A1: ID | B1: Follow-up scope / requirement | C1: Dependency / exit evidence | D1: Priority / timing
A2: F01 | B2: Isolated HTML single-file and ZIP package import with relative assets; supported provider embeds (BR-30/34). | C2: Agree runtime origin, quarantine/inspection, traversal and archive limits, no host credentials, compatible sandbox, exact return state and reviewed fallback. | D2: Next stage after secure MVP; estimate separately.
A3: F02 | B3: SCORM 1.2 single-SCO durable attempts; separate preview, Teacher demonstration and learner tracking. | C3: Isolated runtime adapter, declared data model, acknowledged idempotent commits, resume and error/conformance fixtures. Review existing ScormPlayer/API wrapper before reuse. | D3: After F01; estimate separately.
A4: F03 | B4: SCORM 2004 declared edition/profile and sequencing; multi-SCO if required. | C4: Explicit agreed profile and independent conformance fixtures. SCORM 1.2 or simple HTML launch does not satisfy this. | D4: Later stage; no compatibility claim before tests.
A5: F04 | B5: Collections, favorites and objective/misconception discovery filters (BR-31). | C5: Membership-scoped favorites, non-copying references, paging, combined filter and leakage tests. | D5: Next library increment.
A6: F05 | B6: Shared-resource dependency impact, explicit draft adoption and reauthorization (BR-33). | C6: Visible-scope usage index; candidate?review?draft adoption?revalidate?authorize?new release; active runs unchanged. | D6: Next governance increment; candidates never auto-replace.
A7: F06 | B7: Durable classroom evidence, reflections and Teacher feedback to Author work items (BR-36). | C7: Pinned run/screen/binding context, observed/unobserved/incorrect distinction, consent/retention policy and role-safe records. | D7: Next classroom increment.
A8: F07 | B8: Academic DOCX/PDF/Markdown/JSON imports and mapping review. | C8: Source provenance/hash, missing/ambiguous field findings and explicit acceptance into drafts. No silent academic approval or content loss. | D8: After draft contracts stabilize.
A9: F08 | B9: Full annotation/narration, richer branching, prerequisite graph and advanced object/layout support. | C9: Reviewed object contracts, domain validation, accessibility, return-state tests and representative classroom QA. | D9: Prioritize against BRD traceability gaps.
A10: F09 | B10: Upload quotas, resumable processing and operational scale/link-health automation (BR-35). | C10: MVP already has basic limits/recovery; add representative-load, interrupted transfer, background job retry and health-monitor tests. | D10: Before scaling beyond agreed pilot limits.
A11: F10 | B11: Advanced native simulations, 2D/3D activities, virtual labs, configured AI/provider search. | C11: Scientific invariants/units, capability profiles, academic review, keyboard/static alternatives and configured provider/rights boundaries. | D11: Explicit later acceptance gates.
A12: F11 | B12: Offline/export/import packages and broader rollout. | C12: Exact manifest/asset pinning, private-content exclusion, withdrawal limitations, tested sync/recovery and target-device acceptance. | D12: After online release/delivery is stable.
A13: F12 | B13: Full Rational Numbers migration (114 slides / 523 branches where actual source inventory confirms). | C13: Access to reviewed source and rights; repeatable adapter; math/content/object/order/branch/role comparisons and academic approval. | D13: After representative slice gate; estimate from inventory.

Sheet Revision Notes
A1: Area | B1: Correction
A2: Architecture | B2: Removed pilot stack assumptions from the execution baseline; reuse existing LMS.
A3: Scope | B3: Explicit MVP boundary and separate follow-up backlog.
A4: Status | B4: Unverified completion claims no longer count toward verified progress.
A5: SQL | B5: Review/reuse existing Studio scripts and confirm actual migration state.
A6: Security | B6: Day 19 hardening supplements permissions required from the first implementation.
A7: Release | B7: Validation, exact academic approval, immutable manifests and pinned-run checks strengthened.
A8: Migration | B8: Representative source slice only; full 523-branch migration is separately gated.
A9: Schedule | B9: Provisional working-day sequence with capacity reforecast and same-day dependency rules.
A10: Operations | B10: Staging restore includes referenced assets; Day 28 is conditional go/no-go.
A11: Inputs | B11: Original workbooks retained unchanged; revised copy prepared on 15 October 2026.
